Revision: b86e77937e824940d087b7c5999c79e5c38b00c8
Patch-set: 5
File: tools/checker.py

131:13-131:16
Wed Jan 28 08:26:47 2015 +0000
Author: Nicolas Geoffray <1038443@85c56323-6fa9-3386-8a01-6480fb634889>
UUID: 97662f11_38ed6914
Bytes: 39
Why? In case the logger is not enabled?

131:13-131:16
Mon Feb 02 14:11:05 2015 +0000
Author: David Brazdil <1059815@85c56323-6fa9-3386-8a01-6480fb634889>
Parent: 97662f11_38ed6914
UUID: 17fddfe8_dcafed2a
Bytes: 123
Yep, I did kinda sneak this in here. Logger is disabled during checker_test.py and when something failed, it just said "1".

